<?xml version="1.0" ?>
<sdf version="1.6">
  <model name="aerostate">
    <pose>0 0 1 0 0 0</pose>
    <link name="body">
      <inertial>
        <mass>0.3276</mass>
        <inertia>
          <ixx>0.1</ixx>
          <ixy>0</ixy>
          <ixz>0</ixz>
          <iyy>0.1</iyy>
          <iyz>0</iyz>
          <izz>0.1</izz>
        </inertia>
      </inertial>
      <collision name="collision">
        <geometry>
          <sphere>
            <radius>0.4</radius>  
          </sphere>
        </geometry>
      </collision>
      <visual name="visual">
        <geometry>
          <ellipsoid>
            <radii>0.5 0.3 0.4</radii>
          </ellipsoid>
        </geometry>
        <material>
          <ambient>0.8 0.2 0.2 1</ambient>  
          <diffuse>0.8 0.2 0.2 1</diffuse>
        </material>
      </visual>
      <sensor name="imu_sensor" type="imu">
        <always_on>1</always_on> <!-- Сенсор всегда включен (активен) -->
        <update_rate>100</update_rate> <!-- Частота обновления данных сенсора (Гц) -->
        <visualize>true</visualize> <!-- Визуализация сенсора в Gazebo (отображение оси координат) -->
        <topic>imu</topic> <!-- Топик, на который сенсор публикует данные -->
        <enable_metrics>true</enable_metrics> <!-- Включение метрик производительности сенсора (для отладки) -->
      </sensor>
    </link>
    <link name="camera_link">
    <pose>0 0 -0.2 0 1.57 0</pose> 
    <inertial>
        <mass>0.001</mass>  
        <inertia>
          <ixx>0.00001</ixx>
          <ixy>0</ixy>
          <ixz>0</ixz>
          <iyy>0.00001</iyy>
          <iyz>0</iyz>
          <izz>0.00001</izz>
        </inertia>
      </inertial>
      <collision name="collision">
        <geometry>
          <box>
            <size>0.05 0.05 0.05</size>
          </box>
        </geometry>
      </collision>
    <sensor name="downward_camera" type="camera">
      <camera>
        <horizontal_fov>1.047</horizontal_fov>
        <image>
          <width>320</width>
          <height>240</height>
        </image>
        <clip>
          <near>0.1</near>
          <far>100</far>
        </clip>
      </camera>
      <always_on>true</always_on>
      <update_rate>30</update_rate>
      <visualize>true</visualize>
      <topic>camera</topic>
    </sensor>
  </link>
  <joint name="camera_joint" type="fixed">
    <parent>body</parent>
    <child>camera_link</child>
  </joint>
    <link name='rotor_0'>  <!-- Правый задний -->
    <pose>0.4 -0.2 0 0 0 0</pose>
    <inertial>
        <mass>0.001</mass>  
        <inertia>
          <ixx>0.00001</ixx>
          <ixy>0</ixy>
          <ixz>0</ixz>
          <iyy>0.00001</iyy>
          <iyz>0</iyz>
          <izz>0.00001</izz>
        </inertia>
      </inertial>
      <collision name="collision">
        <geometry>
          <cylinder>
            <radius>0.1</radius>
            <length>0.02</length>
          </cylinder>
        </geometry>
      </collision>
      <visual name="rotor_0_visual">
        <geometry>
          <cylinder>
            <radius>0.1</radius>
            <length>0.02</length>
          </cylinder>
        </geometry>
        <material>
          <ambient>0 0 1 1</ambient>  
        </material>
      </visual>
    </link>
    <joint name="rotor_0_joint" type="revolute">
      <parent>body</parent>
      <child>rotor_0</child>
      <axis>
        <xyz>0 1 0</xyz>
        <limit>
          <lower>-1e+16</lower>
          <upper>1e+16</upper>
        </limit>
      </axis>
    </joint>
    <link name='rotor_1'>  <!-- Левый задний -->
    <pose>0.4 0.2 0 0 0 0</pose>
      <inertial>
        <mass>0.001</mass> 
        <inertia>
          <ixx>0.00001</ixx>
          <ixy>0</ixy>
          <ixz>0</ixz>
          <iyy>0.00001</iyy>
          <iyz>0</iyz>
          <izz>0.00001</izz>
        </inertia>
      </inertial>
      <collision name="collision">
        <geometry>
          <cylinder>
            <radius>0.1</radius>
            <length>0.02</length>
          </cylinder>
        </geometry>
      </collision>
      <visual name="rotor_1_visual">
        <geometry>
          <cylinder>
            <radius>0.1</radius>
            <length>0.02</length>
          </cylinder>
        </geometry>
        <material>
          <ambient>0 0 1 1</ambient>  
        </material>
      </visual>
    </link>
    <joint name="rotor_1_joint" type="revolute">
      <parent>body</parent>
      <child>rotor_1</child>
      <axis>
        <xyz>0 1 0</xyz>
        <limit>
          <lower>-1e+16</lower>
          <upper>1e+16</upper>
        </limit>
      </axis>
    </joint>  
	<link name='rotor_U'>  <!-- Верхний -->
    <pose>0 0 0.3 0 0 0</pose>
      <inertial>
        <mass>0.001</mass>  
        <inertia>
          <ixx>0.00001</ixx>
          <ixy>0</ixy>
          <ixz>0</ixz>
          <iyy>0.00001</iyy>
          <iyz>0</iyz>
          <izz>0.00001</izz>
        </inertia>
      </inertial>
      <collision name="collision">
        <geometry>
          <cylinder>
            <radius>0.1</radius>
            <length>0.02</length>
          </cylinder>
        </geometry>
      </collision>
      <visual name="rotor_U_visual">
        <geometry>
          <cylinder>
            <radius>0.1</radius>
            <length>0.02</length>
          </cylinder>
        </geometry>
        <material>
          <ambient>0 0 1 1</ambient>  
        </material>
      </visual>
    </link>
    <joint name="rotor_U_joint" type="revolute">
      <parent>body</parent>
      <child>rotor_U</child>
      <axis>
        <xyz>0 0 1</xyz>
        <limit>
          <lower>-1e+16</lower>
          <upper>1e+16</upper>
        </limit>
      </axis>
    </joint>  
    <link name='rotor_D'>  <!-- Нижний -->
    <pose>0 0 -0.3 0 0 0</pose>
      <inertial>
        <mass>0.001</mass>  
        <inertia>
          <ixx>0.00001</ixx>
          <ixy>0</ixy>
          <ixz>0</ixz>
          <iyy>0.00001</iyy>
          <iyz>0</iyz>
          <izz>0.00001</izz>
        </inertia>
      </inertial>
      <collision name="collision">
        <geometry>
          <cylinder>
            <radius>0.1</radius>
            <length>0.02</length>
          </cylinder>
        </geometry>
      </collision>
      <visual name="rotor_D_visual">
        <geometry>
          <cylinder>
            <radius>0.1</radius>
            <length>0.02</length>
          </cylinder>
        </geometry>
        <material>
          <ambient>0 0 1 1</ambient> 
        </material>
      </visual>
    </link>
    <joint name="rotor_D_joint" type="revolute">
      <parent>body</parent>
      <child>rotor_D</child>
      <axis>
        <xyz>0 0 1</xyz>
        <limit>
          <lower>-1e+16</lower>
          <upper>1e+16</upper>
        </limit>
      </axis>
    </joint>  
  </model>
</sdf>
